<?xml version="1.0" encoding="UTF-8"?>
<!-- Generated by org.testng.reporters.JUnitReportReporter -->
<testsuite hostname="E5530-2340" name="com.test1.tests.RTest" tests="16" failures="2" timestamp="12 May 2016 12:45:21 GMT" time="1106.833" errors="0">
  <testcase name="testSuccessfulCreateNewClaimant" time="109.520" classname="com.test1.tests.RTest">
    <failure type="java.lang.AssertionError" message="New Claimant has not been created for : AP1TypeR12 expected [true] but found [false]">
      <![CDATA[java.lang.AssertionError: New Claimant has not been created for : AP1TypeR12 expected [true] but found [false]
	at org.testng.Assert.fail(Assert.java:94)
	at org.testng.Assert.failNotEquals(Assert.java:496)
	at org.testng.Assert.assertTrue(Assert.java:42)
	at com.test1.tests.RTest.testSuccessfulCreateNewClaimant(RTest.java:148)
	at sun.reflect.NativeMethodAccessorImpl.invoke0(Native Method)
	at sun.reflect.NativeMethodAccessorImpl.invoke(Unknown Source)
	at sun.reflect.DelegatingMethodAccessorImpl.invoke(Unknown Source)
	at java.lang.reflect.Method.invoke(Unknown Source)
	at org.testng.internal.MethodInvocationHelper.invokeMethod(MethodInvocationHelper.java:85)
	at org.testng.internal.Invoker.invokeMethod(Invoker.java:639)
	at org.testng.internal.Invoker.invokeTestMethod(Invoker.java:821)
	at org.testng.internal.Invoker.invokeTestMethods(Invoker.java:1131)
	at org.testng.internal.TestMethodWorker.invokeTestMethods(TestMethodWorker.java:124)
	at org.testng.internal.TestMethodWorker.run(TestMethodWorker.java:108)
	at org.testng.TestRunner.privateRun(TestRunner.java:773)
	at org.testng.TestRunner.run(TestRunner.java:623)
	at org.testng.SuiteRunner.runTest(SuiteRunner.java:357)
	at org.testng.SuiteRunner.runSequentially(SuiteRunner.java:352)
	at org.testng.SuiteRunner.privateRun(SuiteRunner.java:310)
	at org.testng.SuiteRunner.run(SuiteRunner.java:259)
	at org.testng.SuiteRunnerWorker.runSuite(SuiteRunnerWorker.java:52)
	at org.testng.SuiteRunnerWorker.run(SuiteRunnerWorker.java:86)
	at org.testng.TestNG.runSuitesSequentially(TestNG.java:1185)
	at org.testng.TestNG.runSuitesLocally(TestNG.java:1110)
	at org.testng.TestNG.run(TestNG.java:1018)
	at org.testng.remote.RemoteTestNG.run(RemoteTestNG.java:111)
	at org.testng.remote.RemoteTestNG.initAndRun(RemoteTestNG.java:204)
	at org.testng.remote.RemoteTestNG.main(RemoteTestNG.java:175)
]]>
    </failure>
  </testcase> <!-- testSuccessfulCreateNewClaimant -->
  <testcase name="testSuccessfulDocAttachment" time="63.964" classname="com.test1.tests.RTest"/>
  <testcase name="testSuccessfulDocAttachment" time="64.326" classname="com.test1.tests.RTest"/>
  <testcase name="testSuccessfulDocAttachment" time="64.284" classname="com.test1.tests.RTest"/>
  <testcase name="testSuccessfulCaseSummaryInfo" time="79.717" classname="com.test1.tests.RTest"/>
  <testcase name="testSuccessfulDocAttachment" time="63.805" classname="com.test1.tests.RTest"/>
  <testcase name="testSuccessfulAddNewPriorDealCase" time="44.703" classname="com.test1.tests.RTest"/>
  <testcase name="testSuccessfulDocAttachment" time="63.372" classname="com.test1.tests.RTest"/>
  <testcase name="testSuccessfulCreateNewClaimant" time="113.986" classname="com.test1.tests.RTest">
    <failure type="java.lang.AssertionError" message="New Claimant has not been created for : AE863SGTE12 expected [true] but found [false]">
      <![CDATA[java.lang.AssertionError: New Claimant has not been created for : AE863SGTE12 expected [true] but found [false]
	at org.testng.Assert.fail(Assert.java:94)
	at org.testng.Assert.failNotEquals(Assert.java:496)
	at org.testng.Assert.assertTrue(Assert.java:42)
	at com.test1.tests.RTest.testSuccessfulCreateNewClaimant(RTest.java:148)
	at sun.reflect.NativeMethodAccessorImpl.invoke0(Native Method)
	at sun.reflect.NativeMethodAccessorImpl.invoke(Unknown Source)
	at sun.reflect.DelegatingMethodAccessorImpl.invoke(Unknown Source)
	at java.lang.reflect.Method.invoke(Unknown Source)
	at org.testng.internal.MethodInvocationHelper.invokeMethod(MethodInvocationHelper.java:85)
	at org.testng.internal.Invoker.invokeMethod(Invoker.java:639)
	at org.testng.internal.Invoker.invokeTestMethod(Invoker.java:821)
	at org.testng.internal.Invoker.invokeTestMethods(Invoker.java:1131)
	at org.testng.internal.TestMethodWorker.invokeTestMethods(TestMethodWorker.java:124)
	at org.testng.internal.TestMethodWorker.run(TestMethodWorker.java:108)
	at org.testng.TestRunner.privateRun(TestRunner.java:773)
	at org.testng.TestRunner.run(TestRunner.java:623)
	at org.testng.SuiteRunner.runTest(SuiteRunner.java:357)
	at org.testng.SuiteRunner.runSequentially(SuiteRunner.java:352)
	at org.testng.SuiteRunner.privateRun(SuiteRunner.java:310)
	at org.testng.SuiteRunner.run(SuiteRunner.java:259)
	at org.testng.SuiteRunnerWorker.runSuite(SuiteRunnerWorker.java:52)
	at org.testng.SuiteRunnerWorker.run(SuiteRunnerWorker.java:86)
	at org.testng.TestNG.runSuitesSequentially(TestNG.java:1185)
	at org.testng.TestNG.runSuitesLocally(TestNG.java:1110)
	at org.testng.TestNG.run(TestNG.java:1018)
	at org.testng.remote.RemoteTestNG.run(RemoteTestNG.java:111)
	at org.testng.remote.RemoteTestNG.initAndRun(RemoteTestNG.java:204)
	at org.testng.remote.RemoteTestNG.main(RemoteTestNG.java:175)
]]>
    </failure>
  </testcase> <!-- testSuccessfulCreateNewClaimant -->
  <testcase name="testSuccessfulCaseSummaryInfo" time="75.194" classname="com.test1.tests.RTest"/>
  <testcase name="testSuccessfulDocAttachment" time="63.951" classname="com.test1.tests.RTest"/>
  <testcase name="testSuccessfulAddNewCase" time="43.037" classname="com.test1.tests.RTest"/>
  <testcase name="testSuccessfulDocAttachment" time="64.851" classname="com.test1.tests.RTest"/>
  <testcase name="testSuccessfulDocAttachment" time="64.174" classname="com.test1.tests.RTest"/>
  <testcase name="testSuccessfulDocAttachment" time="63.581" classname="com.test1.tests.RTest"/>
  <testcase name="testSuccessfulDocAttachment" time="64.368" classname="com.test1.tests.RTest"/>
</testsuite> <!-- com.test1.tests.RTest -->
